Workbook

Sheet Sumup
A1: Au NP | B1: Ag equ | C1: Length (nm) | D1: Error (nm) | E1: Section diameter (nm) | F1: Error (nm)
A2: RN199 | B2: 0 | C2: =AVERAGE('RN199'!A3:A124) -> 98.071795 | D2: =_xlfn.STDEV.S('RN199'!A3:A124) -> 2.4688673 | E2: =AVERAGE('RN199'!B3:B137) -> 32.182904 | F2: =_xlfn.STDEV.S('RN199'!B3:B137) -> 1.2159243
B3: 0.2 | C3: =AVERAGE('RN199'!D3:D83) -> 100.08316 | D3: =_xlfn.STDEV.S('RN199'!D3:D83) -> 2.6614031 | E3: =AVERAGE('RN199'!E3:E99) -> 32.891495 | F3: =_xlfn.STDEV.S('RN199'!E3:E99) -> 1.2434871
B4: 0.3 | C4: =AVERAGE('RN199'!G3:G94) -> 98.563598 | D4: =_xlfn.STDEV.S('RN199'!G3:G94) -> 2.8203994 | E4: =AVERAGE('RN199'!E3:E99) -> 32.891495 | F4: =_xlfn.STDEV.S('RN199'!E3:E99) -> 1.2434871
B5: 0.4 | C5: =AVERAGE('RN199'!J3:J141) -> 100.38881 | D5: =_xlfn.STDEV.S('RN199'!J3:J141) -> 2.6541606 | E5: =AVERAGE('RN199'!K3:K156) -> 32.635701 | F5: =_xlfn.STDEV.S('RN199'!K3:K156) -> 1.1488574
B6: 0.5 | C6: =AVERAGE('RN199'!M3:M169) -> 100.21453 | D6: =_xlfn.STDEV.S('RN199'!M3:M169) -> 2.5719068 | E6: =AVERAGE('RN199'!N3:N129) -> 32.654858 | F6: =_xlfn.STDEV.S('RN199'!N3:N129) -> 0.89437893
B7: 0.8 | C7: =AVERAGE('RN199'!P3:P138) -> 100.88294 | D7: =_xlfn.STDEV.S('RN199'!P3:P138) -> 2.4191187 | E7: =AVERAGE('RN199'!Q3:Q165) -> 32.591301 | F7: =_xlfn.STDEV.S('RN199'!Q3:Q165) -> 1.2807421
B8: 2 | C8: =AVERAGE('RN199'!S3:S300) -> 125.48714 | D8: =_xlfn.STDEV.S('RN199'!S3:S300) -> 8.279547 | E8: =AVERAGE('RN199'!T3:T310) -> 32.646065 | F8: =_xlfn.STDEV.S('RN199'!T3:T310) -> 2.1886506
A9: RN62 | B9: 0 | C9: =AVERAGE('RN62'!A3:A222) -> 151.79024 | D9: =_xlfn.STDEV.S('RN62'!A3:A222) -> 4.285465 | E9: =AVERAGE('RN62'!B3:B274) -> 47.267272 | F9: =_xlfn.STDEV.S('RN62'!B3:B274) -> 2.0945079
B10: 0.3 | C10: =AVERAGE('RN62'!D3:D98) -> 147.27989 | D10: =_xlfn.STDEV.S('RN62'!D3:D98) -> 4.1438121 | E10: =AVERAGE('RN62'!E3:E136) -> 46.713761 | F10: =_xlfn.STDEV.S('RN62'!E3:E136) -> 2.0220415
B11: 0.4 | C11: =AVERAGE('RN62'!G3:G114) -> 149.32409 | D11: =_xlfn.STDEV.S('RN62'!G3:G114) -> 3.7039076 | E11: =AVERAGE('RN62'!H3:H163) -> 47.257286 | F11: =_xlfn.STDEV.S('RN62'!H3:H163) -> 1.8750154
B12: 0.5 | C12: =AVERAGE('RN62'!J3:J48) -> 146.83013 | D12: =_xlfn.STDEV.S('RN62'!J3:J48) -> 3.7736084 | E12: =AVERAGE('RN62'!K3:K82) -> 46.1559 | F12: =_xlfn.STDEV.S('RN62'!K3:K82) -> 1.8253678
B13: 0.8 | C13: =AVERAGE('RN62'!M3:M75) -> 152.04037 | D13: =_xlfn.STDEV.S('RN62'!M3:M75) -> 3.8452331 | E13: =AVERAGE('RN62'!N3:N81) -> 47.855 | F13: =_xlfn.STDEV.S('RN62'!N3:N81) -> 1.5699515
B14: 2 | C14: =AVERAGE('RN62'!P3:P66) -> 189.62281 | D14: =_xlfn.STDEV.S('RN62'!P3:P66) -> 11.021515 | E14: =AVERAGE('RN62'!Q3:Q61) -> 46.864153 | F14: =_xlfn.STDEV.S('RN62'!Q3:Q61) -> 2.9699328

Sheet RN199
A1: 0eq | D1: 0.2eq | G1: 0.3eq | J1: 0.4eq | M1: 0.5eq | P1: 0.8eq | S1: 2eq
A2: Length (nm) | B2: Section diameter (nm) | D2: Length (nm) | E2: Section diameter (nm) | G2: Length (nm) | H2: Section diameter (nm) | J2: Length (nm) | K2: Section diameter (nm) | M2: Length (nm) | N2: Section diameter (nm) | P2: Length (nm) | Q2: Section diameter (nm) | S2: Length (nm) | T2: Section diameter (nm)
A3: 99.09 | B3: 31.665 | D3: 101.993 | E3: 34.255 | G3: 99.567 | H3: 32.623 | J3: 101.232 | K3: 32.779 | M3: 99.31 | N3: 31.503 | P3: 100.632 | Q3: 33.134 | S3: 120.36 | T3: 31.747
A4: 99.713 | B4: 32.799 | D4: 99.876 | E4: 33.155 | G4: 97.724 | H4: 33.177 | J4: 99.62 | K4: 32.903 | M4: 96.09 | N4: 31.388 | P4: 97.767 | Q4: 31.335 | S4: 124.813 | T4: 33.544
A5: 98.288 | B5: 31.908 | D5: 97.069 | E5: 33.076 | G5: 97.785 | H5: 29.57 | J5: 99.294 | K5: 33.315 | M5: 94.033 | N5: 32.892 | P5: 97.018 | Q5: 32.481 | S5: 129.872 | T5: 30.386
A6: 99.45 | B6: 32.838 | D6: 98.986 | E6: 32.153 | G6: 100.106 | H6: 30.495 | J6: 102.257 | K6: 32.449 | M6: 98.117 | N6: 34.087 | P6: 96.794 | Q6: 32.383 | S6: 134.958 | T6: 32.278
A7: 95.312 | B7: 32.051 | D7: 100.711 | E7: 34.571 | G7: 99.417 | H7: 33.503 | J7: 102.237 | K7: 32.89 | M7: 103.332 | N7: 31.828 | P7: 100.915 | Q7: 29.887 | S7: 120.967 | T7: 29.747
A8: 97.788 | B8: 31.984 | D8: 99.279 | E8: 33.304 | G8: 97.983 | H8: 33.383 | J8: 102.116 | K8: 32.819 | M8: 91.714 | N8: 31.982 | P8: 98.921 | Q8: 33.283 | S8: 132.913 | T8: 31.019
A9: 101.271 | B9: 32.711 | D9: 100.227 | E9: 31.773 | G9: 98.649 | H9: 33.79 | J9: 101.333 | K9: 30.655 | M9: 101.575 | N9: 32.927 | P9: 97.05 | Q9: 32.772 | S9: 127.848 | T9: 31.038
A10: 98.826 | B10: 33.371 | D10: 100.491 | E10: 33.371 | G10: 90.061 | H10: 31.705 | J10: 99.893 | K10: 31.165 | M10: 101.388 | N10: 32.217 | P10: 96.546 | Q10: 31.783 | S10: 129.747 | T10: 27.877
A11: 93.409 | B11: 31.398 | D11: 99.127 | E11: 33.652 | G11: 98.976 | H11: 30.289 | J11: 96.514 | K11: 31.079 | M11: 101.935 | N11: 32.491 | P11: 99.459 | Q11: 32.288 | S11: 124.076 | T11: 28.509
A12: 95.4 | B12: 34.586 | D12: 97.188 | E12: 33.503 | G12: 98.066 | H12: 30.78 | J12: 99.072 | K12: 30.392 | M12: 99.879 | N12: 33.817 | P12: 101.146 | Q12: 34.055 | S12: 123.458 | T12: 28.509
A13: 96.268 | B13: 32.181 | D13: 103.522 | E13: 29.622 | G13: 97.004 | H13: 32.358 | J13: 95.759 | K13: 31.62 | M13: 97.947 | N13: 32.968 | P13: 97.846 | Q13: 32.069 | S13: 126.078 | T13: 29.774
A14: 97.593 | B14: 31.476 | D14: 102.67 | E14: 32.786 | G14: 96.206 | H14: 31.231 | J14: 98.879 | K14: 31.196 | M14: 96.38 | N14: 33.236 | P14: 101.637 | Q14: 34.74 | S14: 126.006 | T14: 36.126
... A83: 96.736 | B83: 31.03 | D83: 92.71 | E83: 34.896 | G83: 100.411 | H83: 32.656 | J83: 100.442 | K83: 32.125 | M83: 99.214 | N83: 32.157 | P83: 100.255 | Q83: 36.256 | S83: 127.893 | T83: 37.917
A84: 99.067 | B84: 33.863 | E84: 32.896 | G84: 103.198 | H84: 31.682 | J84: 97.575 | K84: 32.786 | M84: 99.061 | N84: 33.385 | P84: 101.552 | Q84: 30.122 | S84: 122.941 | T84: 28.865
A85: 98.116 | B85: 30.677 | E85: 32.586 | G85: 104.163 | H85: 32.024 | J85: 98.986 | K85: 33.164 | M85: 101.268 | N85: 33.239 | P85: 102.753 | Q85: 32.222 | S85: 123.125 | T85: 28.092
A86: 97.674 | B86: 34.914 | E86: 35.548 | G86: 102.64 | H86: 30.455 | J86: 101.507 | K86: 34.672 | M86: 104.888 | N86: 32.44 | P86: 103.486 | Q86: 31.744 | S86: 131.975 | T86: 26.325
A87: 95.304 | B87: 31.837 | E87: 31.868 | G87: 102.326 | H87: 30.677 | J87: 97.886 | K87: 31.968 | M87: 102.469 | N87: 33.52 | P87: 97.484 | Q87: 32.353 | S87: 129.798 | T87: 29.361
A88: 99.562 | B88: 30.935 | E88: 32.413 | G88: 100.018 | H88: 32.025 | J88: 100.26 | K88: 35.316 | M88: 97.65 | N88: 32.629 | P88: 102.736 | Q88: 31.292 | S88: 127.548 | T88: 31.531
A89: 101.605 | B89: 31.984 | E89: 31.558 | G89: 104.576 | H89: 32.878 | J89: 97.315 | K89: 31.677 | M89: 97.913 | N89: 31.132 | P89: 102.329 | Q89: 31.644 | S89: 130.338 | T89: 33.693
A90: 96.113 | B90: 32.151 | E90: 32.756 | G90: 101.017 | H90: 31.544 | J90: 106.352 | K90: 33.99 | M90: 99.254 | N90: 32.001 | P90: 101.556 | Q90: 34.811 | S90: 123.899 | T90: 33.693
A91: 91.25 | B91: 31.777 | E91: 33.913 | G91: 98.704 | H91: 32.243 | J91: 102.273 | K91: 32.385 | M91: 98.932 | N91: 32.462 | P91: 103.026 | Q91: 30.925 | S91: 99.815 | T91: 30.544
A92: 96.506 | B92: 29.829 | E92: 32.049 | G92: 102.599 | H92: 33.307 | J92: 101.904 | K92: 33.024 | M92: 102.552 | N92: 33.804 | P92: 105.44 | Q92: 33.965 | S92: 130.377 | T92: 34.862
A93: 100.087 | B93: 33.544 | E93: 32.509 | G93: 100.713 | H93: 32.05 | J93: 100.033 | K93: 33.014 | M93: 101.913 | N93: 31.707 | P93: 104.235 | Q93: 32.704 | S93: 128.823 | T93: 33.208
A94: 96.721 | B94: 31.504 | E94: 33.032 | G94: 99.77 | H94: 33.074 | J94: 99.126 | K94: 31.968 | M94: 99.163 | N94: 32.97 | P94: 99.327 | Q94: 34.097 | S94: 126.159 | T94: 30.935
A95: 92.485 | B95: 31.086 | E95: 31.444 | H95: 31.384 | J95: 99.387 | K95: 32.097 | M95: 99.573 | N95: 32.931 | P95: 103.795 | Q95: 33.356 | S95: 127.02 | T95: 31.244
A96: 98.071 | B96: 30.833 | E96: 34.099 | H96: 32.007 | J96: 100.834 | K96: 32.119 | M96: 96.891 | N96: 31.88 | P96: 103.053 | Q96: 32.876 | S96: 127.567 | T96: 34.862
A97: 101.697 | B97: 33.294 | E97: 32.668 | H97: 31.604 | J97: 106.977 | K97: 32.097 | M97: 103.917 | N97: 32.416 | P97: 99.22 | Q97: 33.293 | S97: 131.109 | T97: 32.501
A98: 98.469 | B98: 31.768 | E98: 33.8 | H98: 33.49 | J98: 102.277 | K98: 33.129 | M98: 99.256 | N98: 31.136 | P98: 99.558 | Q98: 31.569 | S98: 125.798 | T98: 33.836
A99: 100.782 | B99: 29.309 | E99: 30.676 | H99: 32.68 | J99: 100.873 | K99: 32.876 | M99: 101.532 | N99: 33.385 | P99: 99.232 | Q99: 32.564 | S99: 202.785 | T99: 29.285
A100: 99.73 | B100: 33.668 | H100: 32.413 | J100: 104.254 | K100: 34.653 | M100: 100.919 | N100: 32.909 | P100: 99.959 | Q100: 32.097 | S100: 124.671 | T100: 31.481
A101: 95.267 | B101: 31.899 | H101: 32.772 | J101: 98.214 | K101: 34.545 | M101: 105.635 | N101: 32.624 | P101: 105.083 | Q101: 30.377 | S101: 122.501 | T101: 37.476
A102: 98.624 | B102: 30.334 | H102: 32.899 | J102: 100.086 | K102: 33.139 | M102: 100.884 | N102: 31.725 | P102: 100.033 | Q102: 32.782 | S102: 124.595 | T102: 31.531
A103: 99.237 | B103: 34.108 | H103: 32.211 | J103: 101.075 | K103: 33.481 | M103: 100.854 | N103: 33.768 | P103: 102.564 | Q103: 34.022 | S103: 126.892 | T103: 32.476
A104: 98.624 | B104: 32.151 | H104: 31.069 | J104: 97.894 | K104: 30.329 | M104: 102.231 | N104: 33.711 | P104: 103.139 | Q104: 31.812 | S104: 124.349 | T104: 32.347
A105: 98.479 | B105: 32.75 | H105: 34.358 | J105: 103.052 | K105: 31.742 | M105: 100.169 | N105: 33.092 | P105: 103.196 | Q105: 32.049 | S105: 122.997 | T105: 33.009
A106: 99.538 | B106: 32.641 | H106: 32.371 | J106: 100.84 | K106: 32.695 | M106: 100.032 | N106: 31.578 | P106: 92.739 | Q106: 34.153 | S106: 132.82 | T106: 31.601
A107: 99.513 | B107: 34.098 | H107: 31.803 | J107: 102.09 | K107: 36.442 | M107: 104.825 | N107: 31.628 | P107: 103.025 | Q107: 32.052 | S107: 123.407 | T107: 34.55
A108: 97.605 | B108: 34.811 | H108: 33.354 | J108: 95.426 | K108: 32.56 | M108: 102.343 | N108: 31.856 | P108: 101.575 | Q108: 31.24 | S108: 128.852 | T108: 31.985
...

Sheet RN62
A1: 0eq | D1: 0.3eq | G1: 0.4eq | J1: 0.5eq | M1: 0.8eq | P1: 2eq
A2: Length (nm) | B2: Section diameter (nm) | D2: Length (nm) | E2: Section diameter (nm) | G2: Length (nm) | H2: Section diameter (nm) | J2: Length (nm) | K2: Section diameter (nm) | M2: Length (nm) | N2: Section diameter (nm) | P2: Length (nm) | Q2: Section diameter (nm)
A3: 155.474 | B3: 46.643 | D3: 147.638 | E3: 44.901 | G3: 156.739 | H3: 48.163 | J3: 146.042 | K3: 44.722 | M3: 152.617 | N3: 49.11 | P3: 189.671 | Q3: 46.682
A4: 153.895 | B4: 49.305 | D4: 151.55 | E4: 47.787 | G4: 147.529 | H4: 49.595 | J4: 145.871 | K4: 45.646 | M4: 152.625 | N4: 48.057 | P4: 198.349 | Q4: 46.764
A5: 153.864 | B5: 43.272 | D5: 148.957 | E5: 49.708 | G5: 152.018 | H5: 48.839 | J5: 141.516 | K5: 47.73 | M5: 155.044 | N5: 45.67 | P5: 190.801 | Q5: 52.016
A6: 151.519 | B6: 45.714 | D6: 140.607 | E6: 44.846 | G6: 150.723 | H6: 45.474 | J6: 146.43 | K6: 49.061 | M6: 149.649 | N6: 49.409 | P6: 184.421 | Q6: 46.54
A7: 148.757 | B7: 46.112 | D7: 147.751 | E7: 48.662 | G7: 145.159 | H7: 49.854 | J7: 140.824 | K7: 45.623 | M7: 140.836 | N7: 43.077 | P7: 185.773 | Q7: 40.508
A8: 152.417 | B8: 53.72 | D8: 152.703 | E8: 44.784 | G8: 148.924 | H8: 48.66 | J8: 147.544 | K8: 47.438 | M8: 147.047 | N8: 45.492 | P8: 191.079 | Q8: 51.124
A9: 153.86 | B9: 46.796 | D9: 149.412 | E9: 45.197 | G9: 144.83 | H9: 45.838 | J9: 151.738 | K9: 49.479 | M9: 157.301 | N9: 45.67 | P9: 191.079 | Q9: 46.073
A10: 155.871 | B10: 47.071 | D10: 155.06 | E10: 44.411 | G10: 144.269 | H10: 48.233 | J10: 143.868 | K10: 44.853 | M10: 150.954 | N10: 48.817 | P10: 177.637 | Q10: 49.22
A11: 142.869 | B11: 48.921 | D11: 141.733 | E11: 46.697 | G11: 144.142 | H11: 47.282 | J11: 150.254 | K11: 46.587 | M11: 153.155 | N11: 47.271 | P11: 193.582 | Q11: 37.083
A12: 147.513 | B12: 45 | D12: 159.846 | E12: 50.118 | G12: 148.885 | H12: 45.706 | J12: 151.089 | K12: 49.57 | M12: 147.845 | N12: 46.453 | P12: 193.94 | Q12: 46.118
A13: 152.432 | B13: 48.921 | D13: 150.084 | E13: 44.407 | G13: 146.501 | H13: 46.033 | J13: 148.185 | K13: 47.405 | M13: 150.886 | N13: 49.423 | P13: 191.48 | Q13: 44.947
A14: 154.705 | B14: 44.427 | D14: 153.187 | E14: 49.161 | G14: 147.958 | H14: 48.206 | J14: 151.378 | K14: 46.543 | M14: 147.978 | N14: 48.877 | P14: 207.492 | Q14: 47.061
... A48: 154.412 | B48: 48.823 | D48: 147.747 | E48: 47.347 | G48: 146.857 | H48: 47.011 | J48: 145.157 | K48: 48.259 | M48: 154.032 | N48: 46.882 | P48: 181.12 | Q48: 47.083
A49: 153.504 | B49: 46.796 | D49: 142.388 | E49: 47.282 | G49: 152.233 | H49: 49.047 | K49: 43.611 | M49: 155.831 | N49: 47.276 | P49: 198.285 | Q49: 48.165
A50: 146.85 | B50: 48.774 | D50: 142.044 | E50: 49.624 | G50: 145.21 | H50: 45.024 | K50: 46.019 | M50: 153.065 | N50: 47.7 | P50: 203.094 | Q50: 48.591
A51: 150.782 | B51: 47.999 | D51: 147.989 | E51: 49.617 | G51: 146.761 | H51: 49.656 | K51: 45.849 | M51: 153.197 | N51: 47.501 | P51: 195.474 | Q51: 48.115
A52: 146.019 | B52: 50.045 | D52: 148.654 | E52: 47.39 | G52: 146.186 | H52: 46.435 | K52: 45.426 | M52: 154.406 | N52: 47.689 | P52: 194.73 | Q52: 52.859
A53: 151.773 | B53: 50.91 | D53: 145.359 | E53: 41.734 | G53: 150.842 | H53: 46.268 | K53: 45.371 | M53: 147.346 | N53: 46.85 | P53: 184.801 | Q53: 48.965
A54: 154.211 | B54: 47.687 | D54: 149.376 | E54: 46.918 | G54: 149.99 | H54: 52.263 | K54: 48.923 | M54: 157.654 | N54: 48.885 | P54: 149.169 | Q54: 48.05
A55: 156.439 | B55: 46.847 | D55: 151.862 | E55: 47.674 | G55: 152.657 | H55: 48.158 | K55: 46.056 | M55: 154.582 | N55: 48.36 | P55: 193.458 | Q55: 49.178
A56: 150.82 | B56: 45.185 | D56: 152.371 | E56: 48.336 | G56: 151.15 | H56: 46.693 | K56: 47.075 | M56: 160.376 | N56: 48.093 | P56: 197.711 | Q56: 46.187
A57: 151.68 | B57: 51.085 | D57: 143.048 | E57: 45.502 | G57: 152.912 | H57: 52.026 | K57: 43.621 | M57: 155.756 | N57: 49.121 | P57: 191.099 | Q57: 46.789
A58: 154.353 | B58: 45.106 | D58: 143.74 | E58: 48.956 | G58: 149.98 | H58: 45.723 | K58: 44.444 | M58: 153.26 | N58: 48.43 | P58: 197.373 | Q58: 47.791
A59: 153.369 | B59: 44.641 | D59: 142.149 | E59: 47.57 | G59: 146.76 | H59: 48 | K59: 46.194 | M59: 153.964 | N59: 49.639 | P59: 203.674 | Q59: 50.571
A60: 153.662 | B60: 47.541 | D60: 144.149 | E60: 46.987 | G60: 148.489 | H60: 49.418 | K60: 46.46 | M60: 154.942 | N60: 47.532 | P60: 194.88 | Q60: 49.396
A61: 155.594 | B61: 48.73 | D61: 146.593 | E61: 46.986 | G61: 154.455 | H61: 45.437 | K61: 44.3 | M61: 152.957 | N61: 47.948 | P61: 197.99 | Q61: 45.714
A62: 152.399 | B62: 46.008 | D62: 149.091 | E62: 47.835 | G62: 153.722 | H62: 46.996 | K62: 45.014 | M62: 152.288 | N62: 48.037 | P62: 204.68
A63: 155.739 | B63: 48.164 | D63: 143.47 | E63: 50.218 | G63: 154.306 | H63: 45.645 | K63: 47.096 | M63: 157.377 | N63: 48.731 | P63: 181.057
A64: 155.414 | B64: 48.263 | D64: 139.737 | E64: 45.873 | G64: 144.03 | H64: 46.82 | K64: 45.276 | M64: 154.15 | N64: 50.721 | P64: 189.755
A65: 152.996 | B65: 46.013 | D65: 146.593 | E65: 45.31 | G65: 146.095 | H65: 44.649 | K65: 47.728 | M65: 149.044 | N65: 49.262 | P65: 181.63
A66: 148.909 | B66: 48.073 | D66: 149.566 | E66: 45.029 | G66: 154.957 | H66: 49.427 | K66: 43.132 | M66: 153.075 | N66: 47.209 | P66: 197.151
A67: 151.434 | B67: 47.999 | D67: 144.965 | E67: 45.985 | G67: 145.422 | H67: 46.47 | K67: 47.057 | M67: 149.969 | N67: 48.412
A68: 155.677 | B68: 51.765 | D68: 149.651 | E68: 45.398 | G68: 147.064 | H68: 46.737 | K68: 46.471 | M68: 153.699 | N68: 49.381
A69: 156.919 | B69: 48.1 | D69: 143.754 | E69: 46.121 | G69: 149.788 | H69: 47.625 | K69: 47.035 | M69: 149.221 | N69: 47.304
A70: 151.979 | B70: 47.52 | D70: 143.508 | E70: 44.872 | G70: 154.336 | H70: 46.325 | K70: 45.86 | M70: 155.004 | N70: 50.062
A71: 152.242 | B71: 46.583 | D71: 149.872 | E71: 46.409 | G71: 144.386 | H71: 47.832 | K71: 43.92 | M71: 150.28 | N71: 46.541
A72: 148.28 | B72: 48.742 | D72: 145.419 | E72: 49.224 | G72: 154.08 | H72: 44.786 | K72: 47.256 | M72: 147.741 | N72: 47.649
A73: 157.471 | B73: 46.053 | D73: 147.574 | E73: 46.382 | G73: 153.792 | H73: 45.833 | K73: 51.369 | M73: 152.229 | N73: 47.984
...
